Workbook
Name BatasAset: Pengaturan!$C$9
Name BatasDD: Pengaturan!$C$10
Name DaftarKartu: Kartu!$A$6:$A$105
Name Dasar1: Pengaturan!$C$15
Name Dasar2: Pengaturan!$C$16
Name Dasar3: Pengaturan!$C$17
Name Dasar4: Pengaturan!$C$18
Name Dasar5: Pengaturan!$C$19
Name JmlPutaran: Pengaturan!$C$7
Name LogKartu: Log_Putaran!$C$6:$C$35
Name LogWaktu: Log_Putaran!$D$6:$D$35
Name Modal: Pengaturan!$C$6
Name NamaAcara: Pengaturan!$C$5
Name PesanScript: Pengaturan!$C$27
Name PutaranKini: Log_Putaran!$G$3
Name TahapAktif: Pengaturan!$C$8

Sheet Dashboard
B2: =NamaAcara -> Game Investasi: Kelola Portofolio, Hadapi Skenario
B4: Setiap putaran = 1 kuartal · 5 kelas aset: Sukuk/SBN · Saham · RD Pasar Uang · Emas · RD Campuran · Aset tertinggi menang
B6: PUTARAN | F6: WAKTU SIMULASI | J6: TAHAP | N6: PESERTA AKTIF | R6: ASET TERTINGGI
B7: =PutaranKini&" / "&JmlPutaran -> 2 / 30 | F7: =IF(PutaranKini=0,"Awal",("Tahun "&(INT((PutaranKini-1)/4)+1)&" · Q"&(MOD(PutaranKini-1,4)+1))) -> Tahun 1 · Q2 | J7: ="Tahap "&MIN(INT(MAX(PutaranKini-1,0)/10)+1,IF(JmlPutaran=10,1,3))&IF(JmlPutaran=10," (tunggal)"," dari 3") -> Tahap 1 dari 3 | N7: =COUNTIF(Perhitungan!$AQ$6:$AQ$65,TRUE()) -> 2 | R7: =IF(COUNTIF(Perhitungan!$AQ$6:$AQ$65,TRUE())=0,"-",MAX(Perhitungan!$BW$6:$BW$65)) -> 1.0105294e+08
B8: =IF(PutaranKini>=JmlPutaran,"Permainan selesai 🎉","Sisa "&(JmlPutaran-PutaranKini)&" putaran") -> Sisa 28 putaran | F8: ="≈ "&FIXED(PutaranKini/4,1)&" tahun berjalan" -> ≈ 0.5 tahun berjalan | J8: ="Tahap aktif di pengaturan: "&TahapAktif -> Tahap aktif di pengaturan: 3 | N8: =IF(SUMPRODUCT((Perhitungan!$K$6:$K$65<>"OK")*(Perhitungan!$K$6:$K$65<>"Belum isi"))+SUMPRODUCT((Perhitungan!$S$6:$S$65<>"OK")*(Perhitungan!$S$6:$S$65<>"Belum isi"))+SUMPRODUCT((Perhitungan!$AA$6:$AA$65<>"OK")*(Perhitungan!$AA$6:$AA$65<>"Belum isi"))=0,"Semua input valid ✓","⚠ "&(SUMPRODUCT((Perhitungan!$K$6:$K$65<>"OK")*(Perhitungan!$K$6:$K$65<>"Belum isi"))+SUMPRODUCT((Perhitungan!$S$6:$S$65<>"OK")*(Perhitungan!$S$6:$S$65<>"Belum isi"))+SUMPRODUCT((Perhitungan!$AA$6:$AA$65<>"OK")*(Perhitungan!$AA$6:$AA$65<>"Belum isi")))&" input perlu dicek") -> ⚠ 1 input perlu dicek | R8: =IF(COUNTIF(Perhitungan!$AQ$6:$AQ$65,TRUE())=0,"Menunggu peserta","Rata-rata: "&FIXED(AVERAGEIF(Perhitungan!$AQ$6:$AQ$65,TRUE(),Perhitungan!$BW$6:$BW$65)/1000000,1)&" jt") -> Rata-rata: 100.4 jt
B10: ="Pesan sistem: "&IF(Pengaturan!$C$27="","siap",Pengaturan!$C$27) -> Pesan sistem: Putaran 2: kartu K053 keluar (2026-10-07 16:33:57 WIB).
B12: KARTU SKENARIO PUTARAN INI | M12: 🏆 PAPAN PERINGKAT (TOP 10)
B13: =IF(PutaranKini=0,"—","Putaran "&PutaranKini&" · "&IF(PutaranKini=0,"",INDEX(Log_Putaran!$C$6:$C$35,PutaranKini))) -> Putaran 2 · K053 | E13: =IF(PutaranKini=0,"",INDEX(Kartu!$B$6:$B$105,MATCH(IF(PutaranKini=0,"",INDEX(Log_Putaran!$C$6:$C$35,PutaranKini)),Kartu!$A$6:$A$105,0))) -> Geopolitik & Global | M13: # | N13: ± | O13: Peserta / Tim | R13: Total Aset | T13: Return | U13: Max DD
B14: =IF(PutaranKini=0,"Belum ada kartu — tekan tombol Kocok Kartu untuk memulai",INDEX(Kartu!$C$6:$C$105,MATCH(IF(PutaranKini=0,"",INDEX(Log_Putaran!$C$6:$C$35,PutaranKini)),Kartu!$A$6:$A$105,0))) -> Ketegangan Laut China Selatan | M14: =IF(Data_Grafik!$AI$6="","","🥇") -> 🥇 | N14: =IF(Data_Grafik!$AI$6="","",IF(PutaranKini=0,"–",IF(INDEX(Perhitungan!$CE$6:$CE$65,Data_Grafik!$AI$6)>0,"▲"&INDEX(Perhitungan!$CE$6:$CE$65,Data_Grafik!$AI$6),IF(INDEX(Perhitungan!$CE$6:$CE$65,Data_Grafik!$AI$6)<0,"▼"&-INDEX(Perhitungan!$CE$6:$CE$65,Data_Grafik!$AI$6),"–")))) -> – | O14: =Data_Grafik!B6 | R14: =IF(Data_Grafik!$AI$6="","",INDEX(Perhitungan!$BW$6:$BW$65,Data_Grafik!$AI$6)) -> 1.0105294e+08 | T14: =IF(Data_Grafik!$AI$6="","",INDEX(Perhitungan!$BY$6:$BY$65,Data_Grafik!$AI$6)) -> 0.010529425 | U14: =IF(Data_Grafik!$AI$6="","",INDEX(Perhitungan!$BZ$6:$BZ$65,Data_Grafik!$AI$6)) -> 0
M15: =IF(Data_Grafik!$AI$7="","","🥈") -> 🥈 | N15: =IF(Data_Grafik!$AI$7="","",IF(PutaranKini=0,"–",IF(INDEX(Perhitungan!$CE$6:$CE$65,Data_Grafik!$AI$7)>0,"▲"&INDEX(Perhitungan!$CE$6:$CE$65,Data_Grafik!$AI$7),IF(INDEX(Perhitungan!$CE$6:$CE$65,Data_Grafik!$AI$7)<0,"▼"&-INDEX(Perhitungan!$CE$6:$CE$65,Data_Grafik!$AI$7),"–")))) -> – | O15: =Data_Grafik!B7 -> pandu | R15: =IF(Data_Grafik!$AI$7="","",INDEX(Perhitungan!$BW$6:$BW$65,Data_Grafik!$AI$7)) -> 99748175 | T15: =IF(Data_Grafik!$AI$7="","",INDEX(Perhitungan!$BY$6:$BY$65,Data_Grafik!$AI$7)) -> -0.00251825 | U15: =IF(Data_Grafik!$AI$7="","",INDEX(Perhitungan!$BZ$6:$BZ$65,Data_Grafik!$AI$7)) -> 0.00251825
B16: =IF(PutaranKini=0,"",INDEX(Kartu!$D$6:$D$105,MATCH(IF(PutaranKini=0,"",INDEX(Log_Putaran!$C$6:$C$35,PutaranKini)),Kartu!$A$6:$A$105,0))) -> Insiden militer meningkatkan ketegangan kawasan. | M16: =IF(Data_Grafik!$AI$8="","","🥉") | N16: =IF(Data_Grafik!$AI$8="","",IF(PutaranKini=0,"–",IF(INDEX(Perhitungan!$CE$6:$CE$65,Data_Grafik!$AI$8)>0,"▲"&INDEX(Perhitungan!$CE$6:$CE$65,Data_Grafik!$AI$8),IF(INDEX(Perhitungan!$CE$6:$CE$65,Data_Grafik!$AI$8)<0,"▼"&-INDEX(Perhitungan!$CE$6:$CE$65,Data_Grafik!$AI$8),"–")))) | O16: =Data_Grafik!B8 | R16: =IF(Data_Grafik!$AI$8="","",INDEX(Perhitungan!$BW$6:$BW$65,Data_Grafik!$AI$8)) | T16: =IF(Data_Grafik!$AI$8="","",INDEX(Perhitungan!$BY$6:$BY$65,Data_Grafik!$AI$8)) | U16: =IF(Data_Grafik!$AI$8="","",INDEX(Perhitungan!$BZ$6:$BZ$65,Data_Grafik!$AI$8))
M17: =IF(Data_Grafik!$AI$9="","","4") | N17: =IF(Data_Grafik!$AI$9="","",IF(PutaranKini=0,"–",IF(INDEX(Perhitungan!$CE$6:$CE$65,Data_Grafik!$AI$9)>0,"▲"&INDEX(Perhitungan!$CE$6:$CE$65,Data_Grafik!$AI$9),IF(INDEX(Perhitungan!$CE$6:$CE$65,Data_Grafik!$AI$9)<0,"▼"&-INDEX(Perhitungan!$CE$6:$CE$65,Data_Grafik!$AI$9),"–")))) | O17: =Data_Grafik!B9 | R17: =IF(Data_Grafik!$AI$9="","",INDEX(Perhitungan!$BW$6:$BW$65,Data_Grafik!$AI$9)) | T17: =IF(Data_Grafik!$AI$9="","",INDEX(Perhitungan!$BY$6:$BY$65,Data_Grafik!$AI$9)) | U17: =IF(Data_Grafik!$AI$9="","",INDEX(Perhitungan!$BZ$6:$BZ$65,Data_Grafik!$AI$9))
B18: =IF(PutaranKini=0,"","💡 Mengapa? "&INDEX(Kartu!$E$6:$E$105,MATCH(IF(PutaranKini=0,"",INDEX(Log_Putaran!$C$6:$C$35,PutaranKini)),Kartu!$A$6:$A$105,0))) -> 💡 Mengapa? Risiko geopolitik kawasan menaikkan premi risiko aset Indonesia. Emas diuntungkan. | M18: =IF(Data_Grafik!$AI$10="","","5") | N18: =IF(Data_Grafik!$AI$10="","",IF(PutaranKini=0,"–",IF(INDEX(Perhitungan!$CE$6:$CE$65,Data_Grafik!$AI$10)>0,"▲"&INDEX(Perhitungan!$CE$6:$CE$65,Data_Grafik!$AI$10),IF(INDEX(Perhitungan!$CE$6:$CE$65,Data_Grafik!$AI$10)<0,"▼"&-INDEX(Perhitungan!$CE$6:$CE$65,Data_Grafik!$AI$10),"–")))) | O18: =Data_Grafik!B10 | R18: =IF(Data_Grafik!$AI$10="","",INDEX(Perhitungan!$BW$6:$BW$65,Data_Grafik!$AI$10)) | T18: =IF(Data_Grafik!$AI$10="","",INDEX(Perhitungan!$BY$6:$BY$65,Data_Grafik!$AI$10)) | U18: =IF(Data_Grafik!$AI$10="","",INDEX(Perhitungan!$BZ$6:$BZ$65,Data_Grafik!$AI$10))
M19: =IF(Data_Grafik!$AI$11="","","6") | N19: =IF(Data_Grafik!$AI$11="","",IF(PutaranKini=0,"–",IF(INDEX(Perhitungan!$CE$6:$CE$65,Data_Grafik!$AI$11)>0,"▲"&INDEX(Perhitungan!$CE$6:$CE$65,Data_Grafik!$AI$11),IF(INDEX(Perhitungan!$CE$6:$CE$65,Data_Grafik!$AI$11)<0,"▼"&-INDEX(Perhitungan!$CE$6:$CE$65,Data_Grafik!$AI$11),"–")))) | O19: =Data_Grafik!B11 | R19: =IF(Data_Grafik!$AI$11="","",INDEX(Perhitungan!$BW$6:$BW$65,Data_Grafik!$AI$11)) | T19: =IF(Data_Grafik!$AI$11="","",INDEX(Perhitungan!$BY$6:$BY$65,Data_Grafik!$AI$11)) | U19: =IF(Data_Grafik!$AI$11="","",INDEX(Perhitungan!$BZ$6:$BZ$65,Data_Grafik!$AI$11))
M20: =IF(Data_Grafik!$AI$12="","","7") | N20: =IF(Data_Grafik!$AI$12="","",IF(PutaranKini=0,"–",IF(INDEX(Perhitungan!$CE$6:$CE$65,Data_Grafik!$AI$12)>0,"▲"&INDEX(Perhitungan!$CE$6:$CE$65,Data_Grafik!$AI$12),IF(INDEX(Perhitungan!$CE$6:$CE$65,Data_Grafik!$AI$12)<0,"▼"&-INDEX(Perhitungan!$CE$6:$CE$65,Data_Grafik!$AI$12),"–")))) | O20: =Data_Grafik!B12 | R20: =IF(Data_Grafik!$AI$12="","",INDEX(Perhitungan!$BW$6:$BW$65,Data_Grafik!$AI$12)) | T20: =IF(Data_Grafik!$AI$12="","",INDEX(Perhitungan!$BY$6:$BY$65,Data_Grafik!$AI$12)) | U20: =IF(Data_Grafik!$AI$12="","",INDEX(Perhitungan!$BZ$6:$BZ$65,Data_Grafik!$AI$12))
B21: Sukuk/SBN | D21: Saham | F21: RD Pasar Uang | H21: Emas | J21: RD Campuran | M21: =IF(Data_Grafik!$AI$13="","","8") | N21: =IF(Data_Grafik!$AI$13="","",IF(PutaranKini=0,"–",IF(INDEX(Perhitungan!$CE$6:$CE$65,Data_Grafik!$AI$13)>0,"▲"&INDEX(Perhitungan!$CE$6:$CE$65,Data_Grafik!$AI$13),IF(INDEX(Perhitungan!$CE$6:$CE$65,Data_Grafik!$AI$13)<0,"▼"&-INDEX(Perhitungan!$CE$6:$CE$65,Data_Grafik!$AI$13),"–")))) | O21: =Data_Grafik!B13 | R21: =IF(Data_Grafik!$AI$13="","",INDEX(Perhitungan!$BW$6:$BW$65,Data_Grafik!$AI$13)) | T21: =IF(Data_Grafik!$AI$13="","",INDEX(Perhitungan!$BY$6:$BY$65,Data_Grafik!$AI$13)) | U21: =IF(Data_Grafik!$AI$13="","",INDEX(Perhitungan!$BZ$6:$BZ$65,Data_Grafik!$AI$13))
B22: =IF(PutaranKini=0,"",INDEX(Log_Putaran!$G$6:$G$35,PutaranKini)) -> 0.0175 | D22: =IF(PutaranKini=0,"",INDEX(Log_Putaran!$H$6:$H$35,PutaranKini)) -> -0.04 | F22: =IF(PutaranKini=0,"",INDEX(Log_Putaran!$I$6:$I$35,PutaranKini)) -> 0.011 | H22: =IF(PutaranKini=0,"",INDEX(Log_Putaran!$J$6:$J$35,PutaranKini)) -> 0.062 | J22: =IF(PutaranKini=0,"",INDEX(Log_Putaran!$K$6:$K$35,PutaranKini)) -> -0.0126 | M22: =IF(Data_Grafik!$AI$14="","","9") | N22: =IF(Data_Grafik!$AI$14="","",IF(PutaranKini=0,"–",IF(INDEX(Perhitungan!$CE$6:$CE$65,Data_Grafik!$AI$14)>0,"▲"&INDEX(Perhitungan!$CE$6:$CE$65,Data_Grafik!$AI$14),IF(INDEX(Perhitungan!$CE$6:$CE$65,Data_Grafik!$AI$14)<0,"▼"&-INDEX(Perhitungan!$CE$6:$CE$65,Data_Grafik!$AI$14),"–")))) | O22: =Data_Grafik!B14 | R22: =IF(Data_Grafik!$AI$14="","",INDEX(Perhitungan!$BW$6:$BW$65,Data_Grafik!$AI$14)) | T22: =IF(Data_Grafik!$AI$14="","",INDEX(Perhitungan!$BY$6:$BY$65,Data_Grafik!$AI$14)) | U22: =IF(Data_Grafik!$AI$14="","",INDEX(Perhitungan!$BZ$6:$BZ$65,Data_Grafik!$AI$14))
B23: =IF(PutaranKini=0,"","dasar "&FIXED(Dasar1*100,1)&"% · kartu "&IF(INDEX(Kartu!$F$6:$F$105,MATCH(IF(PutaranKini=0,"",INDEX(Log_Putaran!$C$6:$C$35,PutaranKini)),Kartu!$A$6:$A$105,0))>0,"+","")&FIXED(INDEX(Kartu!$F$6:$F$105,MATCH(IF(PutaranKini=0,"",INDEX(Log_Putaran!$C$6:$C$35,PutaranKini)),Kartu!$A$6:$A$105,0))*100,1)&"%") -> dasar 1.8% · kartu 0.0% | D23: =IF(PutaranKini=0,"","dasar "&FIXED(Dasar2*100,1)&"% · kartu "&IF(INDEX(Kartu!$G$6:$G$105,MATCH(IF(PutaranKini=0,"",INDEX(Log_Putaran!$C$6:$C$35,PutaranKini)),Kartu!$A$6:$A$105,0))>0,"+","")&FIXED(INDEX(Kartu!$G$6:$G$105,MATCH(IF(PutaranKini=0,"",INDEX(Log_Putaran!$C$6:$C$35,PutaranKini)),Kartu!$A$6:$A$105,0))*100,1)&"%") -> dasar 0.0% · kartu -4.0% | F23: =IF(PutaranKini=0,"","dasar "&FIXED(Dasar3*100,1)&"% · kartu "&IF(INDEX(Kartu!$H$6:$H$105,MATCH(IF(PutaranKini=0,"",INDEX(Log_Putaran!$C$6:$C$35,PutaranKini)),Kartu!$A$6:$A$105,0))>0,"+","")&FIXED(INDEX(Kartu!$H$6:$H$105,MATCH(IF(PutaranKini=0,"",INDEX(Log_Putaran!$C$6:$C$35,PutaranKini)),Kartu!$A$6:$A$105,0))*100,1)&"%") -> dasar 1.1% · kartu 0.0% | H23: =IF(PutaranKini=0,"","dasar "&FIXED(Dasar4*100,1)&"% · kartu "&IF(INDEX(Kartu!$I$6:$I$105,MATCH(IF(PutaranKini=0,"",INDEX(Log_Putaran!$C$6:$C$35,PutaranKini)),Kartu!$A$6:$A$105,0))>0,"+","")&FIXED(INDEX(Kartu!$I$6:$I$105,MATCH(IF(PutaranKini=0,"",INDEX(Log_Putaran!$C$6:$C$35,PutaranKini)),Kartu!$A$6:$A$105,0))*100,1)&"%") -> dasar 0.2% · kartu +6.0% | J23: =IF(PutaranKini=0,"","dasar "&FIXED(Dasar5*100,1)&"% · kartu "&IF(INDEX(Kartu!$J$6:$J$105,MATCH(IF(PutaranKini=0,"",INDEX(Log_Putaran!$C$6:$C$35,PutaranKini)),Kartu!$A$6:$A$105,0))>0,"+","")&FIXED(INDEX(Kartu!$J$6:$J$105,MATCH(IF(PutaranKini=0,"",INDEX(Log_Putaran!$C$6:$C$35,PutaranKini)),Kartu!$A$6:$A$105,0))*100,1)&"%") -> dasar 0.7% · kartu -2.0% | M23: =IF(Data_Grafik!$AI$15="","","10") | N23: =IF(Data_Grafik!$AI$15="","",IF(PutaranKini=0,"–",IF(INDEX(Perhitungan!$CE$6:$CE$65,Data_Grafik!$AI$15)>0,"▲"&INDEX(Perhitungan!$CE$6:$CE$65,Data_Grafik!$AI$15),IF(INDEX(Perhitungan!$CE$6:$CE$65,Data_Grafik!$AI$15)<0,"▼"&-INDEX(Perhitungan!$CE$6:$CE$65,Data_Grafik!$AI$15),"–")))) | O23: =Data_Grafik!B15 | R23: =IF(Data_Grafik!$AI$15="","",INDEX(Perhitungan!$BW$6:$BW$65,Data_Grafik!$AI$15)) | T23: =IF(Data_Grafik!$AI$15="","",INDEX(Perhitungan!$BY$6:$BY$65,Data_Grafik!$AI$15)) | U23: =IF(Data_Grafik!$AI$15="","",INDEX(Perhitungan!$BZ$6:$BZ$65,Data_Grafik!$AI$15))
B25: RIWAYAT 5 KARTU TERAKHIR | M25: ="🏅 INVESTOR TANGGUH (max drawdown ≤ "&ROUND(BatasDD*100,0)&"%"&")" -> 🏅 INVESTOR TANGGUH (max drawdown ≤ 10%)
B26: =IF((PutaranKini-0)<1,"","Putaran "&(PutaranKini-0)) -> Putaran 2 | D26: =IF((PutaranKini-0)<1,"",INDEX(Log_Putaran!$E$6:$E$35,(PutaranKini-0))&" · "&INDEX(Log_Putaran!$F$6:$F$35,(PutaranKini-0))) -> Ketegangan Laut China Selatan · Geopolitik & Global | M26: 1 | N26: =IF(Data_Grafik!$C$29="","(belum ada)",Data_Grafik!B29) | R26: =IF(Data_Grafik!$C$29="","",INDEX(Perhitungan!$BW$6:$BW$65,Data_Grafik!$C$29)) -> 1.0105294e+08 | T26: =IF(Data_Grafik!$C$29="","",INDEX(Perhitungan!$BZ$6:$BZ$65,Data_Grafik!$C$29)) -> 0
B27: =IF((PutaranKini-1)<1,"","Putaran "&(PutaranKini-1)) -> Putaran 1 | D27: =IF((PutaranKini-1)<1,"",INDEX(Log_Putaran!$E$6:$E$35,(PutaranKini-1))&" · "&INDEX(Log_Putaran!$F$6:$F$35,(PutaranKini-1))) -> Asing Lepas SBN Besar-besaran · Pasar Modal | M27: 2 | N27: =IF(Data_Grafik!$C$30="","(belum ada)",Data_Grafik!B30) -> pandu | R27: =IF(Data_Grafik!$C$30="","",INDEX(Perhitungan!$BW$6:$BW$65,Data_Grafik!$C$30)) -> 99748175 | T27: =IF(Data_Grafik!$C$30="","",INDEX(Perhitungan!$BZ$6:$BZ$65,Data_Grafik!$C$30)) -> 0.00251825
B28: =IF((PutaranKini-2)<1,"","Putaran "&(PutaranKini-2)) | D28: =IF((PutaranKini-2)<1,"",INDEX(Log_Putaran!$E$6:$E$35,(PutaranKini-2))&" · "&INDEX(Log_Putaran!$F$6:$F$35,(PutaranKini-2))) | M28: 3 | N28: =IF(Data_Grafik!$C$31="","(belum ada)",Data_Grafik!B31) -> (belum ada) | R28: =IF(Data_Grafik!$C$31="","",INDEX(Perhitungan!$BW$6:$BW$65,Data_Grafik!$C$31)) | T28: =IF(Data_Grafik!$C$31="","",INDEX(Perhitungan!$BZ$6:$BZ$65,Data_Grafik!$C$31))
B29: =IF((PutaranKini-3)<1,"","Putaran "&(PutaranKini-3)) | D29: =IF((PutaranKini-3)<1,"",INDEX(Log_Putaran!$E$6:$E$35,(PutaranKini-3))&" · "&INDEX(Log_Putaran!$F$6:$F$35,(PutaranKini-3))) | M29: Peringkat utama = total aset tertinggi. 'Investor Tangguh' = aset tertinggi di antara peserta yang penurunan terdalamnya dari puncak tetap kecil — hasil bagus dengan risiko terkendali.
B30: =IF((PutaranKini-4)<1,"","Putaran "&(PutaranKini-4)) | D30: =IF((PutaranKini-4)<1,"",INDEX(Log_Putaran!$E$6:$E$35,(PutaranKini-4))&" · "&INDEX(Log_Putaran!$F$6:$F$35,(PutaranKini-4)))
B32: GRAFIK PERKEMBANGAN

Sheet Panduan
B2: Panduan Fasilitator & Setup
B5: A. ALUR PERMAINAN
B6: 1. Registrasi: bagikan kode peserta (P01, P02, … lihat sheet Peserta) ke tiap peserta/tim.
B7: 2. Peserta mengisi Microsoft Forms: kode, nama, Tahap = 1, dan porsi 5 aset dalam persen utuh (total 100). Data masuk otomatis ke sheet Input.
B8: 3. Cek Dashboard: 'Peserta aktif' bertambah. Jika muncul '⚠ input perlu dicek', buka sheet Perhitungan (status merah) dan minta peserta submit ulang. Submission TERAKHIR yang dipakai.
B9: 4. Tutup form (Forms → 'Accepting responses' OFF). Tekan tombol Kocok Kartu → bacakan narasi & penjelasan kartu → leaderboard dan grafik ter-update. Ulangi per putaran.
B10: 5. Mode 30 putaran: setelah putaran 10, buka form lagi; peserta submit Tahap = 2 (nilai asetnya lihat di leaderboard). Peserta yang tidak submit memakai komposisi tahap sebelumnya.
B11: Setelah semua masuk, tutup form, lalu ubah 'Tahap aktif' di Pengaturan menjadi 2. Tombol Kocok Kartu sengaja menolak masuk tahap berikutnya sebelum ini dilakukan. Sama untuk Tahap 3 setelah putaran 20.
B12: 6. Aset di awal tahap baru = total aset akhir tahap sebelumnya × porsi baru (rebalancing otomatis).
B13: 7. Pemenang: aset tertinggi di akhir permainan. Penghargaan tambahan 'Investor Tangguh' untuk menonjolkan pentingnya mengelola risiko.
B14: B. SETUP SEKALI (Microsoft 365)
B15: 1. Simpan workbook ini di OneDrive for Business atau SharePoint (akun kantor). Nama tabel di sheet Input harus tetap 'tblInput'.
... B34: • Excel for the web tidak menjalankan VBA; karena itu tombol memakai Office Scripts.

Sheet Pengaturan
B2: Pengaturan Game
B3: Sel berlatar kuning = boleh diubah fasilitator. Angka biru = asumsi/input.
B5: Nama acara | C5: Game Investasi: Kelola Portofolio, Hadapi Skenario | D5: Tampil di banner Dashboard.
B6: Modal awal per peserta (Rp) | C6: 100000000 | D6: Sesuai permintaan: Rp100 juta.
B7: Jumlah putaran (10 atau 30) | C7: 30 | D7: 10 = satu tahap. 30 = tiga tahap × 10 putaran, peserta boleh ganti komposisi di awal tahap 2 dan 3.
B8: Tahap aktif (1/2/3) | C8: 3 | D8: Tombol Kocok Kartu menolak masuk tahap berikutnya sebelum angka ini dinaikkan. Naikkan SETELAH alokasi baru terkumpul & form ditutup.
B9: Batas maksimum per aset | C9: 1 | D9: 100% = tanpa batas. Isi misal 60% untuk memaksa diversifikasi.
B10: Batas max drawdown 'Investor Tangguh' | C10: 0.1 | D10: Penghargaan kedua: aset tertinggi di antara peserta yang penurunan terdalamnya (dari puncak) tidak melebihi batas ini.
B13: Imbal hasil dasar per putaran (1 putaran = 1 kuartal)
B14: Aset | C14: Imbal hasil dasar / kuartal | D14: Dasar asumsi
B15: Sukuk/SBN | C15: 0.0175 | D15: Imbalan sukuk negara 7% per tahun = 1,75% per kuartal, tetap setiap putaran. Diasumsikan sukuk negara ritel yang dipegang hingga jatuh tempo: imbalan & pokok dijamin negara, tidak terpengaruh kartu.
B16: Saham | C16: 0 | D16: 0% (Opsi A): hasil saham murni dari kartu. 50 kartu naik & 50 kartu turun dengan besaran berpasangan (total ±369%). Ubah ke 1,5% bila ingin memasukkan dividen/pertumbuhan laba (Opsi B).
B17: RD Pasar Uang | C17: 0.011 | D17: Imbal hasil deposito/instrumen pasar uang ±4,5% per tahun; hampir tanpa fluktuasi.
B18: Emas | C18: 0.002 | D18: Emas tidak memberi imbal hasil; naik saat krisis/inflasi/rupiah melemah, turun saat risk-on atau dolar kuat. Rata-rata ±7%/tahun, volatilitas ±9%/tahun.
B19: RD Campuran | C19: 0.0074 | D19: Kombinasi 50% saham + 45% sukuk + 5% pasar uang, dikurangi biaya 0,1%/kuartal. Dampak kartu = 1/2 dampak saham (juga 50 naik/50 turun).
B21: Hasil uji 20.000 simulasi acak (kartu + imbal hasil dasar):
B22: • 10 putaran: Sukuk pasti +18,9%. Saham median −3%, peluang rugi 55%, 1 dari 20 permainan rugi ≥41%. RD Campuran median +7%, peluang rugi 33%.
B23: • Walau naik & turun seimbang, saham cenderung rugi: naik 10% lalu turun 10% = −1% (volatility drag). Poin edukasi untuk penutup game.
B24: • Saham tetap bisa menang besar kalau beruntung (1 dari 20 permainan +50% atau lebih), tetapi peluangnya seperti lempar koin. Sukuk memberi hasil pasti.
B27: Pesan terakhir dari script (otomatis) | C27: Putaran 2: kartu K053 keluar (2026-10-07 16:33:57 WIB).

Sheet Kartu
B2: Daftar 100 Kartu Skenario
B3: Dampak = perubahan TAMBAHAN di luar imbal hasil dasar, per kuartal. Boleh diedit (angka biru).
A5: ID | B5: Kategori | C5: Judul | D5: Narasi (dibacakan) | E5: Penjelasan ekonomi | F5: Sukuk/SBN | G5: Saham | H5: RD Pasar Uang | I5: Emas | J5: RD Campuran
A6: K001 | B6: Moneter & Suku Bunga | C6: BI Rate Naik 25 bps | D6: Bank Indonesia menaikkan suku bunga acuan untuk meredam inflasi. | E6: Suku bunga naik → biaya pinjaman emiten naik dan valuasi saham tertekan. Imbal hasil pasar uang ikut naik. Pemegang sukuk negara ritel tidak terdampak: imbalan tetap dibayar. | F6: 0 | G6: -0.05 | H6: 0.002 | I6: -0.025 | J6: -0.025
A7: K002 | B7: Moneter & Suku Bunga | C7: BI Rate Naik 50 bps | D7: BI menaikkan suku bunga secara agresif untuk menahan pelemahan rupiah. | E7: Kenaikan besar menekan valuasi saham. Instrumen pasar uang justru diuntungkan karena bunga deposito naik. Pemegang sukuk negara ritel tidak terdampak: imbalan tetap dibayar. | F7: 0 | G7: -0.1 | H7: 0.004 | I7: -0.035 | J7: -0.05
A8: K003 | B8: Moneter & Suku Bunga | C8: BI Rate Turun 25 bps | D8: Inflasi jinak, BI memangkas suku bunga acuan. | E8: Biaya dana lebih murah mendorong laba dan valuasi saham. Imbal hasil pasar uang sedikit turun. | F8: 0 | G8: 0.04 | H8: -0.002 | I8: 0.025 | J8: 0.02
A9: K004 | B9: Moneter & Suku Bunga | C9: BI Rate Turun 50 bps | D9: BI memangkas suku bunga agresif untuk mendorong pertumbuhan. | E9: Pemangkasan besar memicu reli saham karena biaya dana turun tajam. Imbal hasil pasar uang turun. | F9: 0 | G9: 0.12 | H9: -0.003 | I9: 0.035 | J9: 0.06
A10: K005 | B10: Moneter & Suku Bunga | C10: BI Rate Ditahan | D10: BI mempertahankan suku bunga sesuai ekspektasi pasar. | E10: Tidak ada kejutan kebijakan. Pasar tenang dan cenderung sedikit positif karena ketidakpastian berkurang. | F10: 0 | G10: 0.03 | H10: 0 | I10: 0 | J10: 0.015
A11: K006 | B11: Moneter & Suku Bunga | C11: The Fed Naikkan Suku Bunga | D11: Bank sentral AS menaikkan suku bunga; dolar AS menguat. | E11: Selisih imbal hasil RI–AS menyempit → investor asing menarik dana dari pasar saham. Emas tertekan karena dolar kuat. Pemegang sukuk negara ritel tidak terdampak: imbalan tetap dibayar. | F11: 0 | G11: -0.06 | H11: 0.001 | I11: -0.07 | J11: -0.03
A12: K007 | B12: Moneter & Suku Bunga | C12: The Fed Pangkas Suku Bunga | D12: The Fed menurunkan suku bunga; dolar AS melemah. | E12: Dana global mencari imbal hasil lebih tinggi di negara berkembang, termasuk saham Indonesia. Emas naik karena bunga riil turun. | F12: 0 | G12: 0.18 | H12: 0 | I12: 0.095 | J12: 0.09
A13: K008 | B13: Moneter & Suku Bunga | C13: Sinyal 'Higher for Longer' | D13: Bank sentral global memberi sinyal suku bunga tinggi bertahan lama. | E13: Harapan penurunan bunga pupus → saham terkoreksi. Emas tertekan karena opportunity cost memegang emas naik. Pemegang sukuk negara ritel tidak terdampak: imbalan tetap dibayar. | F13: 0 | G13: -0.06 | H13: 0.002 | I13: -0.05 | J13: -0.03
A14: K009 | B14: Moneter & Suku Bunga | C14: Likuiditas Perbankan Ketat | D14: Bank berebut dana pihak ketiga; bunga deposito naik. | E14: Likuiditas ketat menaikkan yield pasar dan menekan harga aset berisiko. Reksa dana pasar uang menikmati bunga deposito yang lebih tinggi. | F14: 0 | G14: -0.04 | H14: 0.004 | I14: 0 | J14: -0.02
A15: K010 | B15: Moneter & Suku Bunga | C15: Pelonggaran Makroprudensial | D15: BI melonggarkan giro wajib minimum dan aturan kredit. | E15: Likuiditas bank bertambah sehingga kredit dan konsumsi terdorong. Saham, terutama perbankan, naik. | F15: 0 | G15: 0.04 | H15: -0.001 | I15: 0 | J15: 0.02
A16: K011 | B16: Moneter & Suku Bunga | C16: Intervensi Rupiah Berhasil | D16: BI melakukan intervensi triple intervention; rupiah kembali stabil. | E16: Stabilitas kurs mengurangi risiko nilai tukar bagi investor asing, sehingga dana kembali ke pasar saham. Emas dalam rupiah sedikit turun. | F16: 0 | G16: 0.04 | H16: 0 | I16: -0.025 | J16: 0.02
A17: K012 | B17: Moneter & Suku Bunga | C17: Kurva Yield Mendatar | D17: Yield jangka pendek naik mendekati jangka panjang; pasar khawatir perlambatan. | E17: Pasar khawatir perlambatan ekonomi → saham tertekan kekhawatiran laba, emas diburu. Pemegang sukuk negara ritel tidak terdampak: imbalan tetap dibayar. | F17: 0 | G17: -0.06 | H17: 0 | I17: 0.05 | J17: -0.03
... A105: K100 | B105: Tenang / Netral | C105: Pasar Wait and See | D105: Investor menunggu arah kebijakan menjelang pengumuman penting. | E105: Ketidakpastian membuat investor menahan diri dan sedikit menambah aset aman. | F105: 0 | G105: -0.02 | H105: 0 | I105: 0.01 | J105: -0.01

Sheet Log_Putaran
B2: Log Putaran
B3: Kolom C (ID) & D (Waktu) diisi tombol Kocok Kartu. Bila perlu manual, ketik ID kartu (mis. K017) di kolom C. | F3: Putaran terkini: | G3: =COUNTIF(C6:C35,"?*") -> 2
A5: Putaran | B5: Tahap | C5: Kartu ID | D5: Waktu | E5: Judul | F5: Kategori | G5: Return Sukuk/SBN | H5: Return Saham | I5: Return RD Pasar Uang | J5: Return Emas | K5: Return RD Campuran | L5: Faktor tahap Sukuk/SBN | M5: Faktor tahap Saham | N5: Faktor tahap RD Pasar Uang | O5: Faktor tahap Emas | P5: Faktor tahap RD Campuran | Q5: Indeks Sukuk/SBN | R5: Indeks Saham | S5: Indeks RD Pasar Uang | T5: Indeks Emas | U5: Indeks RD Campuran
A6: 1 | B6: 1 | C6: K040 | D6: 46302.69 | E6: =IF($C6="","",INDEX(Kartu!$C$6:$C$105,MATCH($C6,Kartu!$A$6:$A$105,0))) -> Asing Lepas SBN Besar-besaran | F6: =IF($C6="","",INDEX(Kartu!$B$6:$B$105,MATCH($C6,Kartu!$A$6:$A$105,0))) -> Pasar Modal | G6: =IF($C6="","",Dasar1+INDEX(Kartu!$F$6:$F$105,MATCH($C6,Kartu!$A$6:$A$105,0))) -> 0.0175 | H6: =IF($C6="","",Dasar2+INDEX(Kartu!$G$6:$G$105,MATCH($C6,Kartu!$A$6:$A$105,0))) -> -0.03 | I6: =IF($C6="","",Dasar3+INDEX(Kartu!$H$6:$H$105,MATCH($C6,Kartu!$A$6:$A$105,0))) -> 0.011 | J6: =IF($C6="","",Dasar4+INDEX(Kartu!$I$6:$I$105,MATCH($C6,Kartu!$A$6:$A$105,0))) -> 0.022 | K6: =IF($C6="","",Dasar5+INDEX(Kartu!$J$6:$J$105,MATCH($C6,Kartu!$A$6:$A$105,0))) -> -0.0076 | L6: =IF($C6="","",1+G6) -> 1.0175 | M6: =IF($C6="","",1+H6) -> 0.97 | N6: =IF($C6="","",1+I6) -> 1.011 | O6: =IF($C6="","",1+J6) -> 1.022 | P6: =IF($C6="","",1+K6) -> 0.9924 | Q6: =IF($C6="","",100*(1+G6)) -> 101.75 | R6: =IF($C6="","",100*(1+H6)) -> 97 | S6: =IF($C6="","",100*(1+I6)) -> 101.1 | T6: =IF($C6="","",100*(1+J6)) -> 102.2 | U6: =IF($C6="","",100*(1+K6)) -> 99.24
A7: 2 | B7: 1 | C7: K053 | D7: 46302.69 | E7: =IF($C7="","",INDEX(Kartu!$C$6:$C$105,MATCH($C7,Kartu!$A$6:$A$105,0))) -> Ketegangan Laut China Selatan | F7: =IF($C7="","",INDEX(Kartu!$B$6:$B$105,MATCH($C7,Kartu!$A$6:$A$105,0))) -> Geopolitik & Global | G7: =IF($C7="","",Dasar1+INDEX(Kartu!$F$6:$F$105,MATCH($C7,Kartu!$A$6:$A$105,0))) -> 0.0175 | H7: =IF($C7="","",Dasar2+INDEX(Kartu!$G$6:$G$105,MATCH($C7,Kartu!$A$6:$A$105,0))) -> -0.04 | I7: =IF($C7="","",Dasar3+INDEX(Kartu!$H$6:$H$105,MATCH($C7,Kartu!$A$6:$A$105,0))) -> 0.011 | J7: =IF($C7="","",Dasar4+INDEX(Kartu!$I$6:$I$105,MATCH($C7,Kartu!$A$6:$A$105,0))) -> 0.062 | K7: =IF($C7="","",Dasar5+INDEX(Kartu!$J$6:$J$105,MATCH($C7,Kartu!$A$6:$A$105,0))) -> -0.0126 | L7: =IF($C7="","",L6*(1+G7)) -> 1.0353063 | M7: =IF($C7="","",M6*(1+H7)) -> 0.9312 | N7: =IF($C7="","",N6*(1+I7)) -> 1.022121 | O7: =IF($C7="","",O6*(1+J7)) -> 1.085364 | P7: =IF($C7="","",P6*(1+K7)) -> 0.97989576 | Q7: =IF($C7="","",Q6*(1+G7)) -> 103.53063 | R7: =IF($C7="","",R6*(1+H7)) -> 93.12 | S7: =IF($C7="","",S6*(1+I7)) -> 102.2121 | T7: =IF($C7="","",T6*(1+J7)) -> 108.5364 | U7: =IF($C7="","",U6*(1+K7)) -> 97.989576
A8: 3 | B8: 1 | E8: =IF($C8="","",INDEX(Kartu!$C$6:$C$105,MATCH($C8,Kartu!$A$6:$A$105,0))) | F8: =IF($C8="","",INDEX(Kartu!$B$6:$B$105,MATCH($C8,Kartu!$A$6:$A$105,0))) | G8: =IF($C8="","",Dasar1+INDEX(Kartu!$F$6:$F$105,MATCH($C8,Kartu!$A$6:$A$105,0))) | H8: =IF($C8="","",Dasar2+INDEX(Kartu!$G$6:$G$105,MATCH($C8,Kartu!$A$6:$A$105,0))) | I8: =IF($C8="","",Dasar3+INDEX(Kartu!$H$6:$H$105,MATCH($C8,Kartu!$A$6:$A$105,0))) | J8: =IF($C8="","",Dasar4+INDEX(Kartu!$I$6:$I$105,MATCH($C8,Kartu!$A$6:$A$105,0))) | K8: =IF($C8="","",Dasar5+INDEX(Kartu!$J$6:$J$105,MATCH($C8,Kartu!$A$6:$A$105,0))) | L8: =IF($C8="","",L7*(1+G8)) | M8: =IF($C8="","",M7*(1+H8)) | N8: =IF($C8="","",N7*(1+I8)) | O8: =IF($C8="","",O7*(1+J8)) | P8: =IF($C8="","",P7*(1+K8)) | Q8: =IF($C8="","",Q7*(1+G8)) | R8: =IF($C8="","",R7*(1+H8)) | S8: =IF($C8="","",S7*(1+I8)) | T8: =IF($C8="","",T7*(1+J8)) | U8: =IF($C8="","",U7*(1+K8))
A9: 4 | B9: 1 | E9: =IF($C9="","",INDEX(Kartu!$C$6:$C$105,MATCH($C9,Kartu!$A$6:$A$105,0))) | F9: =IF($C9="","",INDEX(Kartu!$B$6:$B$105,MATCH($C9,Kartu!$A$6:$A$105,0))) | G9: =IF($C9="","",Dasar1+INDEX(Kartu!$F$6:$F$105,MATCH($C9,Kartu!$A$6:$A$105,0))) | H9: =IF($C9="","",Dasar2+INDEX(Kartu!$G$6:$G$105,MATCH($C9,Kartu!$A$6:$A$105,0))) | I9: =IF($C9="","",Dasar3+INDEX(Kartu!$H$6:$H$105,MATCH($C9,Kartu!$A$6:$A$105,0))) | J9: =IF($C9="","",Dasar4+INDEX(Kartu!$I$6:$I$105,MATCH($C9,Kartu!$A$6:$A$105,0))) | K9: =IF($C9="","",Dasar5+INDEX(Kartu!$J$6:$J$105,MATCH($C9,Kartu!$A$6:$A$105,0))) | L9: =IF($C9="","",L8*(1+G9)) | M9: =IF($C9="","",M8*(1+H9)) | N9: =IF($C9="","",N8*(1+I9)) | O9: =IF($C9="","",O8*(1+J9)) | P9: =IF($C9="","",P8*(1+K9)) | Q9: =IF($C9="","",Q8*(1+G9)) | R9: =IF($C9="","",R8*(1+H9)) | S9: =IF($C9="","",S8*(1+I9)) | T9: =IF($C9="","",T8*(1+J9)) | U9: =IF($C9="","",U8*(1+K9))
A10: 5 | B10: 1 | E10: =IF($C10="","",INDEX(Kartu!$C$6:$C$105,MATCH($C10,Kartu!$A$6:$A$105,0))) | F10: =IF($C10="","",INDEX(Kartu!$B$6:$B$105,MATCH($C10,Kartu!$A$6:$A$105,0))) | G10: =IF($C10="","",Dasar1+INDEX(Kartu!$F$6:$F$105,MATCH($C10,Kartu!$A$6:$A$105,0))) | H10: =IF($C10="","",Dasar2+INDEX(Kartu!$G$6:$G$105,MATCH($C10,Kartu!$A$6:$A$105,0))) | I10: =IF($C10="","",Dasar3+INDEX(Kartu!$H$6:$H$105,MATCH($C10,Kartu!$A$6:$A$105,0))) | J10: =IF($C10="","",Dasar4+INDEX(Kartu!$I$6:$I$105,MATCH($C10,Kartu!$A$6:$A$105,0))) | K10: =IF($C10="","",Dasar5+INDEX(Kartu!$J$6:$J$105,MATCH($C10,Kartu!$A$6:$A$105,0))) | L10: =IF($C10="","",L9*(1+G10)) | M10: =IF($C10="","",M9*(1+H10)) | N10: =IF($C10="","",N9*(1+I10)) | O10: =IF($C10="","",O9*(1+J10)) | P10: =IF($C10="","",P9*(1+K10)) | Q10: =IF($C10="","",Q9*(1+G10)) | R10: =IF($C10="","",R9*(1+H10)) | S10: =IF($C10="","",S9*(1+I10)) | T10: =IF($C10="","",T9*(1+J10)) | U10: =IF($C10="","",U9*(1+K10))
A11: 6 | B11: 1 | E11: =IF($C11="","",INDEX(Kartu!$C$6:$C$105,MATCH($C11,Kartu!$A$6:$A$105,0))) | F11: =IF($C11="","",INDEX(Kartu!$B$6:$B$105,MATCH($C11,Kartu!$A$6:$A$105,0))) | G11: =IF($C11="","",Dasar1+INDEX(Kartu!$F$6:$F$105,MATCH($C11,Kartu!$A$6:$A$105,0))) | H11: =IF($C11="","",Dasar2+INDEX(Kartu!$G$6:$G$105,MATCH($C11,Kartu!$A$6:$A$105,0))) | I11: =IF($C11="","",Dasar3+INDEX(Kartu!$H$6:$H$105,MATCH($C11,Kartu!$A$6:$A$105,0))) | J11: =IF($C11="","",Dasar4+INDEX(Kartu!$I$6:$I$105,MATCH($C11,Kartu!$A$6:$A$105,0))) | K11: =IF($C11="","",Dasar5+INDEX(Kartu!$J$6:$J$105,MATCH($C11,Kartu!$A$6:$A$105,0))) | L11: =IF($C11="","",L10*(1+G11)) | M11: =IF($C11="","",M10*(1+H11)) | N11: =IF($C11="","",N10*(1+I11)) | O11: =IF($C11="","",O10*(1+J11)) | P11: =IF($C11="","",P10*(1+K11)) | Q11: =IF($C11="","",Q10*(1+G11)) | R11: =IF($C11="","",R10*(1+H11)) | S11: =IF($C11="","",S10*(1+I11)) | T11: =IF($C11="","",T10*(1+J11)) | U11: =IF($C11="","",U10*(1+K11))
A12: 7 | B12: 1 | E12: =IF($C12="","",INDEX(Kartu!$C$6:$C$105,MATCH($C12,Kartu!$A$6:$A$105,0))) | F12: =IF($C12="","",INDEX(Kartu!$B$6:$B$105,MATCH($C12,Kartu!$A$6:$A$105,0))) | G12: =IF($C12="","",Dasar1+INDEX(Kartu!$F$6:$F$105,MATCH($C12,Kartu!$A$6:$A$105,0))) | H12: =IF($C12="","",Dasar2+INDEX(Kartu!$G$6:$G$105,MATCH($C12,Kartu!$A$6:$A$105,0))) | I12: =IF($C12="","",Dasar3+INDEX(Kartu!$H$6:$H$105,MATCH($C12,Kartu!$A$6:$A$105,0))) | J12: =IF($C12="","",Dasar4+INDEX(Kartu!$I$6:$I$105,MATCH($C12,Kartu!$A$6:$A$105,0))) | K12: =IF($C12="","",Dasar5+INDEX(Kartu!$J$6:$J$105,MATCH($C12,Kartu!$A$6:$A$105,0))) | L12: =IF($C12="","",L11*(1+G12)) | M12: =IF($C12="","",M11*(1+H12)) | N12: =IF($C12="","",N11*(1+I12)) | O12: =IF($C12="","",O11*(1+J12)) | P12: =IF($C12="","",P11*(1+K12)) | Q12: =IF($C12="","",Q11*(1+G12)) | R12: =IF($C12="","",R11*(1+H12)) | S12: =IF($C12="","",S11*(1+I12)) | T12: =IF($C12="","",T11*(1+J12)) | U12: =IF($C12="","",U11*(1+K12))
A13: 8 | B13: 1 | E13: =IF($C13="","",INDEX(Kartu!$C$6:$C$105,MATCH($C13,Kartu!$A$6:$A$105,0))) | F13: =IF($C13="","",INDEX(Kartu!$B$6:$B$105,MATCH($C13,Kartu!$A$6:$A$105,0))) | G13: =IF($C13="","",Dasar1+INDEX(Kartu!$F$6:$F$105,MATCH($C13,Kartu!$A$6:$A$105,0))) | H13: =IF($C13="","",Dasar2+INDEX(Kartu!$G$6:$G$105,MATCH($C13,Kartu!$A$6:$A$105,0))) | I13: =IF($C13="","",Dasar3+INDEX(Kartu!$H$6:$H$105,MATCH($C13,Kartu!$A$6:$A$105,0))) | J13: =IF($C13="","",Dasar4+INDEX(Kartu!$I$6:$I$105,MATCH($C13,Kartu!$A$6:$A$105,0))) | K13: =IF($C13="","",Dasar5+INDEX(Kartu!$J$6:$J$105,MATCH($C13,Kartu!$A$6:$A$105,0))) | L13: =IF($C13="","",L12*(1+G13)) | M13: =IF($C13="","",M12*(1+H13)) | N13: =IF($C13="","",N12*(1+I13)) | O13: =IF($C13="","",O12*(1+J13)) | P13: =IF($C13="","",P12*(1+K13)) | Q13: =IF($C13="","",Q12*(1+G13)) | R13: =IF($C13="","",R12*(1+H13)) | S13: =IF($C13="","",S12*(1+I13)) | T13: =IF($C13="","",T12*(1+J13)) | U13: =IF($C13="","",U12*(1+K13))
A14: 9 | B14: 1 | E14: =IF($C14="","",INDEX(Kartu!$C$6:$C$105,MATCH($C14,Kartu!$A$6:$A$105,0))) | F14: =IF($C14="","",INDEX(Kartu!$B$6:$B$105,MATCH($C14,Kartu!$A$6:$A$105,0))) | G14: =IF($C14="","",Dasar1+INDEX(Kartu!$F$6:$F$105,MATCH($C14,Kartu!$A$6:$A$105,0))) | H14: =IF($C14="","",Dasar2+INDEX(Kartu!$G$6:$G$105,MATCH($C14,Kartu!$A$6:$A$105,0))) | I14: =IF($C14="","",Dasar3+INDEX(Kartu!$H$6:$H$105,MATCH($C14,Kartu!$A$6:$A$105,0))) | J14: =IF($C14="","",Dasar4+INDEX(Kartu!$I$6:$I$105,MATCH($C14,Kartu!$A$6:$A$105,0))) | K14: =IF($C14="","",Dasar5+INDEX(Kartu!$J$6:$J$105,MATCH($C14,Kartu!$A$6:$A$105,0))) | L14: =IF($C14="","",L13*(1+G14)) | M14: =IF($C14="","",M13*(1+H14)) | N14: =IF($C14="","",N13*(1+I14)) | O14: =IF($C14="","",O13*(1+J14)) | P14: =IF($C14="","",P13*(1+K14)) | Q14: =IF($C14="","",Q13*(1+G14)) | R14: =IF($C14="","",R13*(1+H14)) | S14: =IF($C14="","",S13*(1+I14)) | T14: =IF($C14="","",T13*(1+J14)) | U14: =IF($C14="","",U13*(1+K14))
A15: 10 | B15: 1 | E15: =IF($C15="","",INDEX(Kartu!$C$6:$C$105,MATCH($C15,Kartu!$A$6:$A$105,0))) | F15: =IF($C15="","",INDEX(Kartu!$B$6:$B$105,MATCH($C15,Kartu!$A$6:$A$105,0))) | G15: =IF($C15="","",Dasar1+INDEX(Kartu!$F$6:$F$105,MATCH($C15,Kartu!$A$6:$A$105,0))) | H15: =IF($C15="","",Dasar2+INDEX(Kartu!$G$6:$G$105,MATCH($C15,Kartu!$A$6:$A$105,0))) | I15: =IF($C15="","",Dasar3+INDEX(Kartu!$H$6:$H$105,MATCH($C15,Kartu!$A$6:$A$105,0))) | J15: =IF($C15="","",Dasar4+INDEX(Kartu!$I$6:$I$105,MATCH($C15,Kartu!$A$6:$A$105,0))) | K15: =IF($C15="","",Dasar5+INDEX(Kartu!$J$6:$J$105,MATCH($C15,Kartu!$A$6:$A$105,0))) | L15: =IF($C15="","",L14*(1+G15)) | M15: =IF($C15="","",M14*(1+H15)) | N15: =IF($C15="","",N14*(1+I15)) | O15: =IF($C15="","",O14*(1+J15)) | P15: =IF($C15="","",P14*(1+K15)) | Q15: =IF($C15="","",Q14*(1+G15)) | R15: =IF($C15="","",R14*(1+H15)) | S15: =IF($C15="","",S14*(1+I15)) | T15: =IF($C15="","",T14*(1+J15)) | U15: =IF($C15="","",U14*(1+K15))
A16: 11 | B16: 2 | E16: =IF($C16="","",INDEX(Kartu!$C$6:$C$105,MATCH($C16,Kartu!$A$6:$A$105,0))) | F16: =IF($C16="","",INDEX(Kartu!$B$6:$B$105,MATCH($C16,Kartu!$A$6:$A$105,0))) | G16: =IF($C16="","",Dasar1+INDEX(Kartu!$F$6:$F$105,MATCH($C16,Kartu!$A$6:$A$105,0))) | H16: =IF($C16="","",Dasar2+INDEX(Kartu!$G$6:$G$105,MATCH($C16,Kartu!$A$6:$A$105,0))) | I16: =IF($C16="","",Dasar3+INDEX(Kartu!$H$6:$H$105,MATCH($C16,Kartu!$A$6:$A$105,0))) | J16: =IF($C16="","",Dasar4+INDEX(Kartu!$I$6:$I$105,MATCH($C16,Kartu!$A$6:$A$105,0))) | K16: =IF($C16="","",Dasar5+INDEX(Kartu!$J$6:$J$105,MATCH($C16,Kartu!$A$6:$A$105,0))) | L16: =IF($C16="","",1+G16) | M16: =IF($C16="","",1+H16) | N16: =IF($C16="","",1+I16) | O16: =IF($C16="","",1+J16) | P16: =IF($C16="","",1+K16) | Q16: =IF($C16="","",Q15*(1+G16)) | R16: =IF($C16="","",R15*(1+H16)) | S16: =IF($C16="","",S15*(1+I16)) | T16: =IF($C16="","",T15*(1+J16)) | U16: =IF($C16="","",U15*(1+K16))
A17: 12 | B17: 2 | E17: =IF($C17="","",INDEX(Kartu!$C$6:$C$105,MATCH($C17,Kartu!$A$6:$A$105,0))) | F17: =IF($C17="","",INDEX(Kartu!$B$6:$B$105,MATCH($C17,Kartu!$A$6:$A$105,0))) | G17: =IF($C17="","",Dasar1+INDEX(Kartu!$F$6:$F$105,MATCH($C17,Kartu!$A$6:$A$105,0))) | H17: =IF($C17="","",Dasar2+INDEX(Kartu!$G$6:$G$105,MATCH($C17,Kartu!$A$6:$A$105,0))) | I17: =IF($C17="","",Dasar3+INDEX(Kartu!$H$6:$H$105,MATCH($C17,Kartu!$A$6:$A$105,0))) | J17: =IF($C17="","",Dasar4+INDEX(Kartu!$I$6:$I$105,MATCH($C17,Kartu!$A$6:$A$105,0))) | K17: =IF($C17="","",Dasar5+INDEX(Kartu!$J$6:$J$105,MATCH($C17,Kartu!$A$6:$A$105,0))) | L17: =IF($C17="","",L16*(1+G17)) | M17: =IF($C17="","",M16*(1+H17)) | N17: =IF($C17="","",N16*(1+I17)) | O17: =IF($C17="","",O16*(1+J17)) | P17: =IF($C17="","",P16*(1+K17)) | Q17: =IF($C17="","",Q16*(1+G17)) | R17: =IF($C17="","",R16*(1+H17)) | S17: =IF($C17="","",S16*(1+I17)) | T17: =IF($C17="","",T16*(1+J17)) | U17: =IF($C17="","",U16*(1+K17))
A18: 13 | B18: 2 | E18: =IF($C18="","",INDEX(Kartu!$C$6:$C$105,MATCH($C18,Kartu!$A$6:$A$105,0))) | F18: =IF($C18="","",INDEX(Kartu!$B$6:$B$105,MATCH($C18,Kartu!$A$6:$A$105,0))) | G18: =IF($C18="","",Dasar1+INDEX(Kartu!$F$6:$F$105,MATCH($C18,Kartu!$A$6:$A$105,0))) | H18: =IF($C18="","",Dasar2+INDEX(Kartu!$G$6:$G$105,MATCH($C18,Kartu!$A$6:$A$105,0))) | I18: =IF($C18="","",Dasar3+INDEX(Kartu!$H$6:$H$105,MATCH($C18,Kartu!$A$6:$A$105,0))) | J18: =IF($C18="","",Dasar4+INDEX(Kartu!$I$6:$I$105,MATCH($C18,Kartu!$A$6:$A$105,0))) | K18: =IF($C18="","",Dasar5+INDEX(Kartu!$J$6:$J$105,MATCH($C18,Kartu!$A$6:$A$105,0))) | L18: =IF($C18="","",L17*(1+G18)) | M18: =IF($C18="","",M17*(1+H18)) | N18: =IF($C18="","",N17*(1+I18)) | O18: =IF($C18="","",O17*(1+J18)) | P18: =IF($C18="","",P17*(1+K18)) | Q18: =IF($C18="","",Q17*(1+G18)) | R18: =IF($C18="","",R17*(1+H18)) | S18: =IF($C18="","",S17*(1+I18)) | T18: =IF($C18="","",T17*(1+J18)) | U18: =IF($C18="","",U17*(1+K18))
A19: 14 | B19: 2 | E19: =IF($C19="","",INDEX(Kartu!$C$6:$C$105,MATCH($C19,Kartu!$A$6:$A$105,0))) | F19: =IF($C19="","",INDEX(Kartu!$B$6:$B$105,MATCH($C19,Kartu!$A$6:$A$105,0))) | G19: =IF($C19="","",Dasar1+INDEX(Kartu!$F$6:$F$105,MATCH($C19,Kartu!$A$6:$A$105,0))) | H19: =IF($C19="","",Dasar2+INDEX(Kartu!$G$6:$G$105,MATCH($C19,Kartu!$A$6:$A$105,0))) | I19: =IF($C19="","",Dasar3+INDEX(Kartu!$H$6:$H$105,MATCH($C19,Kartu!$A$6:$A$105,0))) | J19: =IF($C19="","",Dasar4+INDEX(Kartu!$I$6:$I$105,MATCH($C19,Kartu!$A$6:$A$105,0))) | K19: =IF($C19="","",Dasar5+INDEX(Kartu!$J$6:$J$105,MATCH($C19,Kartu!$A$6:$A$105,0))) | L19: =IF($C19="","",L18*(1+G19)) | M19: =IF($C19="","",M18*(1+H19)) | N19: =IF($C19="","",N18*(1+I19)) | O19: =IF($C19="","",O18*(1+J19)) | P19: =IF($C19="","",P18*(1+K19)) | Q19: =IF($C19="","",Q18*(1+G19)) | R19: =IF($C19="","",R18*(1+H19)) | S19: =IF($C19="","",S18*(1+I19)) | T19: =IF($C19="","",T18*(1+J19)) | U19: =IF($C19="","",U18*(1+K19))
A20: 15 | B20: 2 | E20: =IF($C20="","",INDEX(Kartu!$C$6:$C$105,MATCH($C20,Kartu!$A$6:$A$105,0))) | F20: =IF($C20="","",INDEX(Kartu!$B$6:$B$105,MATCH($C20,Kartu!$A$6:$A$105,0))) | G20: =IF($C20="","",Dasar1+INDEX(Kartu!$F$6:$F$105,MATCH($C20,Kartu!$A$6:$A$105,0))) | H20: =IF($C20="","",Dasar2+INDEX(Kartu!$G$6:$G$105,MATCH($C20,Kartu!$A$6:$A$105,0))) | I20: =IF($C20="","",Dasar3+INDEX(Kartu!$H$6:$H$105,MATCH($C20,Kartu!$A$6:$A$105,0))) | J20: =IF($C20="","",Dasar4+INDEX(Kartu!$I$6:$I$105,MATCH($C20,Kartu!$A$6:$A$105,0))) | K20: =IF($C20="","",Dasar5+INDEX(Kartu!$J$6:$J$105,MATCH($C20,Kartu!$A$6:$A$105,0))) | L20: =IF($C20="","",L19*(1+G20)) | M20: =IF($C20="","",M19*(1+H20)) | N20: =IF($C20="","",N19*(1+I20)) | O20: =IF($C20="","",O19*(1+J20)) | P20: =IF($C20="","",P19*(1+K20)) | Q20: =IF($C20="","",Q19*(1+G20)) | R20: =IF($C20="","",R19*(1+H20)) | S20: =IF($C20="","",S19*(1+I20)) | T20: =IF($C20="","",T19*(1+J20)) | U20: =IF($C20="","",U19*(1+K20))
A21: 16 | B21: 2 | E21: =IF($C21="","",INDEX(Kartu!$C$6:$C$105,MATCH($C21,Kartu!$A$6:$A$105,0))) | F21: =IF($C21="","",INDEX(Kartu!$B$6:$B$105,MATCH($C21,Kartu!$A$6:$A$105,0))) | G21: =IF($C21="","",Dasar1+INDEX(Kartu!$F$6:$F$105,MATCH($C21,Kartu!$A$6:$A$105,0))) | H21: =IF($C21="","",Dasar2+INDEX(Kartu!$G$6:$G$105,MATCH($C21,Kartu!$A$6:$A$105,0))) | I21: =IF($C21="","",Dasar3+INDEX(Kartu!$H$6:$H$105,MATCH($C21,Kartu!$A$6:$A$105,0))) | J21: =IF($C21="","",Dasar4+INDEX(Kartu!$I$6:$I$105,MATCH($C21,Kartu!$A$6:$A$105,0))) | K21: =IF($C21="","",Dasar5+INDEX(Kartu!$J$6:$J$105,MATCH($C21,Kartu!$A$6:$A$105,0))) | L21: =IF($C21="","",L20*(1+G21)) | M21: =IF($C21="","",M20*(1+H21)) | N21: =IF($C21="","",N20*(1+I21)) | O21: =IF($C21="","",O20*(1+J21)) | P21: =IF($C21="","",P20*(1+K21)) | Q21: =IF($C21="","",Q20*(1+G21)) | R21: =IF($C21="","",R20*(1+H21)) | S21: =IF($C21="","",S20*(1+I21)) | T21: =IF($C21="","",T20*(1+J21)) | U21: =IF($C21="","",U20*(1+K21))
A22: 17 | B22: 2 | E22: =IF($C22="","",INDEX(Kartu!$C$6:$C$105,MATCH($C22,Kartu!$A$6:$A$105,0))) | F22: =IF($C22="","",INDEX(Kartu!$B$6:$B$105,MATCH($C22,Kartu!$A$6:$A$105,0))) | G22: =IF($C22="","",Dasar1+INDEX(Kartu!$F$6:$F$105,MATCH($C22,Kartu!$A$6:$A$105,0))) | H22: =IF($C22="","",Dasar2+INDEX(Kartu!$G$6:$G$105,MATCH($C22,Kartu!$A$6:$A$105,0))) | I22: =IF($C22="","",Dasar3+INDEX(Kartu!$H$6:$H$105,MATCH($C22,Kartu!$A$6:$A$105,0))) | J22: =IF($C22="","",Dasar4+INDEX(Kartu!$I$6:$I$105,MATCH($C22,Kartu!$A$6:$A$105,0))) | K22: =IF($C22="","",Dasar5+INDEX(Kartu!$J$6:$J$105,MATCH($C22,Kartu!$A$6:$A$105,0))) | L22: =IF($C22="","",L21*(1+G22)) | M22: =IF($C22="","",M21*(1+H22)) | N22: =IF($C22="","",N21*(1+I22)) | O22: =IF($C22="","",O21*(1+J22)) | P22: =IF($C22="","",P21*(1+K22)) | Q22: =IF($C22="","",Q21*(1+G22)) | R22: =IF($C22="","",R21*(1+H22)) | S22: =IF($C22="","",S21*(1+I22)) | T22: =IF($C22="","",T21*(1+J22)) | U22: =IF($C22="","",U21*(1+K22))
A23: 18 | B23: 2 | E23: =IF($C23="","",INDEX(Kartu!$C$6:$C$105,MATCH($C23,Kartu!$A$6:$A$105,0))) | F23: =IF($C23="","",INDEX(Kartu!$B$6:$B$105,MATCH($C23,Kartu!$A$6:$A$105,0))) | G23: =IF($C23="","",Dasar1+INDEX(Kartu!$F$6:$F$105,MATCH($C23,Kartu!$A$6:$A$105,0))) | H23: =IF($C23="","",Dasar2+INDEX(Kartu!$G$6:$G$105,MATCH($C23,Kartu!$A$6:$A$105,0))) | I23: =IF($C23="","",Dasar3+INDEX(Kartu!$H$6:$H$105,MATCH($C23,Kartu!$A$6:$A$105,0))) | J23: =IF($C23="","",Dasar4+INDEX(Kartu!$I$6:$I$105,MATCH($C23,Kartu!$A$6:$A$105,0))) | K23: =IF($C23="","",Dasar5+INDEX(Kartu!$J$6:$J$105,MATCH($C23,Kartu!$A$6:$A$105,0))) | L23: =IF($C23="","",L22*(1+G23)) | M23: =IF($C23="","",M22*(1+H23)) | N23: =IF($C23="","",N22*(1+I23)) | O23: =IF($C23="","",O22*(1+J23)) | P23: =IF($C23="","",P22*(1+K23)) | Q23: =IF($C23="","",Q22*(1+G23)) | R23: =IF($C23="","",R22*(1+H23)) | S23: =IF($C23="","",S22*(1+I23)) | T23: =IF($C23="","",T22*(1+J23)) | U23: =IF($C23="","",U22*(1+K23))
A24: 19 | B24: 2 | E24: =IF($C24="","",INDEX(Kartu!$C$6:$C$105,MATCH($C24,Kartu!$A$6:$A$105,0))) | F24: =IF($C24="","",INDEX(Kartu!$B$6:$B$105,MATCH($C24,Kartu!$A$6:$A$105,0))) | G24: =IF($C24="","",Dasar1+INDEX(Kartu!$F$6:$F$105,MATCH($C24,Kartu!$A$6:$A$105,0))) | H24: =IF($C24="","",Dasar2+INDEX(Kartu!$G$6:$G$105,MATCH($C24,Kartu!$A$6:$A$105,0))) | I24: =IF($C24="","",Dasar3+INDEX(Kartu!$H$6:$H$105,MATCH($C24,Kartu!$A$6:$A$105,0))) | J24: =IF($C24="","",Dasar4+INDEX(Kartu!$I$6:$I$105,MATCH($C24,Kartu!$A$6:$A$105,0))) | K24: =IF($C24="","",Dasar5+INDEX(Kartu!$J$6:$J$105,MATCH($C24,Kartu!$A$6:$A$105,0))) | L24: =IF($C24="","",L23*(1+G24)) | M24: =IF($C24="","",M23*(1+H24)) | N24: =IF($C24="","",N23*(1+I24)) | O24: =IF($C24="","",O23*(1+J24)) | P24: =IF($C24="","",P23*(1+K24)) | Q24: =IF($C24="","",Q23*(1+G24)) | R24: =IF($C24="","",R23*(1+H24)) | S24: =IF($C24="","",S23*(1+I24)) | T24: =IF($C24="","",T23*(1+J24)) | U24: =IF($C24="","",U23*(1+K24))
A25: 20 | B25: 2 | E25: =IF($C25="","",INDEX(Kartu!$C$6:$C$105,MATCH($C25,Kartu!$A$6:$A$105,0))) | F25: =IF($C25="","",INDEX(Kartu!$B$6:$B$105,MATCH($C25,Kartu!$A$6:$A$105,0))) | G25: =IF($C25="","",Dasar1+INDEX(Kartu!$F$6:$F$105,MATCH($C25,Kartu!$A$6:$A$105,0))) | H25: =IF($C25="","",Dasar2+INDEX(Kartu!$G$6:$G$105,MATCH($C25,Kartu!$A$6:$A$105,0))) | I25: =IF($C25="","",Dasar3+INDEX(Kartu!$H$6:$H$105,MATCH($C25,Kartu!$A$6:$A$105,0))) | J25: =IF($C25="","",Dasar4+INDEX(Kartu!$I$6:$I$105,MATCH($C25,Kartu!$A$6:$A$105,0))) | K25: =IF($C25="","",Dasar5+INDEX(Kartu!$J$6:$J$105,MATCH($C25,Kartu!$A$6:$A$105,0))) | L25: =IF($C25="","",L24*(1+G25)) | M25: =IF($C25="","",M24*(1+H25)) | N25: =IF($C25="","",N24*(1+I25)) | O25: =IF($C25="","",O24*(1+J25)) | P25: =IF($C25="","",P24*(1+K25)) | Q25: =IF($C25="","",Q24*(1+G25)) | R25: =IF($C25="","",R24*(1+H25)) | S25: =IF($C25="","",S24*(1+I25)) | T25: =IF($C25="","",T24*(1+J25)) | U25: =IF($C25="","",U24*(1+K25))
A26: 21 | B26: 3 | E26: =IF($C26="","",INDEX(Kartu!$C$6:$C$105,MATCH($C26,Kartu!$A$6:$A$105,0))) | F26: =IF($C26="","",INDEX(Kartu!$B$6:$B$105,MATCH($C26,Kartu!$A$6:$A$105,0))) | G26: =IF($C26="","",Dasar1+INDEX(Kartu!$F$6:$F$105,MATCH($C26,Kartu!$A$6:$A$105,0))) | H26: =IF($C26="","",Dasar2+INDEX(Kartu!$G$6:$G$105,MATCH($C26,Kartu!$A$6:$A$105,0))) | I26: =IF($C26="","",Dasar3+INDEX(Kartu!$H$6:$H$105,MATCH($C26,Kartu!$A$6:$A$105,0))) | J26: =IF($C26="","",Dasar4+INDEX(Kartu!$I$6:$I$105,MATCH($C26,Kartu!$A$6:$A$105,0))) | K26: =IF($C26="","",Dasar5+INDEX(Kartu!$J$6:$J$105,MATCH($C26,Kartu!$A$6:$A$105,0))) | L26: =IF($C26="","",1+G26) | M26: =IF($C26="","",1+H26) | N26: =IF($C26="","",1+I26) | O26: =IF($C26="","",1+J26) | P26: =IF($C26="","",1+K26) | Q26: =IF($C26="","",Q25*(1+G26)) | R26: =IF($C26="","",R25*(1+H26)) | S26: =IF($C26="","",S25*(1+I26)) | T26: =IF($C26="","",T25*(1+J26)) | U26: =IF($C26="","",U25*(1+K26))
A27: 22 | B27: 3 | E27: =IF($C27="","",INDEX(Kartu!$C$6:$C$105,MATCH($C27,Kartu!$A$6:$A$105,0))) | F27: =IF($C27="","",INDEX(Kartu!$B$6:$B$105,MATCH($C27,Kartu!$A$6:$A$105,0))) | G27: =IF($C27="","",Dasar1+INDEX(Kartu!$F$6:$F$105,MATCH($C27,Kartu!$A$6:$A$105,0))) | H27: =IF($C27="","",Dasar2+INDEX(Kartu!$G$6:$G$105,MATCH($C27,Kartu!$A$6:$A$105,0))) | I27: =IF($C27="","",Dasar3+INDEX(Kartu!$H$6:$H$105,MATCH($C27,Kartu!$A$6:$A$105,0))) | J27: =IF($C27="","",Dasar4+INDEX(Kartu!$I$6:$I$105,MATCH($C27,Kartu!$A$6:$A$105,0))) | K27: =IF($C27="","",Dasar5+INDEX(Kartu!$J$6:$J$105,MATCH($C27,Kartu!$A$6:$A$105,0))) | L27: =IF($C27="","",L26*(1+G27)) | M27: =IF($C27="","",M26*(1+H27)) | N27: =IF($C27="","",N26*(1+I27)) | O27: =IF($C27="","",O26*(1+J27)) | P27: =IF($C27="","",P26*(1+K27)) | Q27: =IF($C27="","",Q26*(1+G27)) | R27: =IF($C27="","",R26*(1+H27)) | S27: =IF($C27="","",S26*(1+I27)) | T27: =IF($C27="","",T26*(1+J27)) | U27: =IF($C27="","",U26*(1+K27))
A28: 23 | B28: 3 | E28: =IF($C28="","",INDEX(Kartu!$C$6:$C$105,MATCH($C28,Kartu!$A$6:$A$105,0))) | F28: =IF($C28="","",INDEX(Kartu!$B$6:$B$105,MATCH($C28,Kartu!$A$6:$A$105,0))) | G28: =IF($C28="","",Dasar1+INDEX(Kartu!$F$6:$F$105,MATCH($C28,Kartu!$A$6:$A$105,0))) | H28: =IF($C28="","",Dasar2+INDEX(Kartu!$G$6:$G$105,MATCH($C28,Kartu!$A$6:$A$105,0))) | I28: =IF($C28="","",Dasar3+INDEX(Kartu!$H$6:$H$105,MATCH($C28,Kartu!$A$6:$A$105,0))) | J28: =IF($C28="","",Dasar4+INDEX(Kartu!$I$6:$I$105,MATCH($C28,Kartu!$A$6:$A$105,0))) | K28: =IF($C28="","",Dasar5+INDEX(Kartu!$J$6:$J$105,MATCH($C28,Kartu!$A$6:$A$105,0))) | L28: =IF($C28="","",L27*(1+G28)) | M28: =IF($C28="","",M27*(1+H28)) | N28: =IF($C28="","",N27*(1+I28)) | O28: =IF($C28="","",O27*(1+J28)) | P28: =IF($C28="","",P27*(1+K28)) | Q28: =IF($C28="","",Q27*(1+G28)) | R28: =IF($C28="","",R27*(1+H28)) | S28: =IF($C28="","",S27*(1+I28)) | T28: =IF($C28="","",T27*(1+J28)) | U28: =IF($C28="","",U27*(1+K28))
A29: 24 | B29: 3 | E29: =IF($C29="","",INDEX(Kartu!$C$6:$C$105,MATCH($C29,Kartu!$A$6:$A$105,0))) | F29: =IF($C29="","",INDEX(Kartu!$B$6:$B$105,MATCH($C29,Kartu!$A$6:$A$105,0))) | G29: =IF($C29="","",Dasar1+INDEX(Kartu!$F$6:$F$105,MATCH($C29,Kartu!$A$6:$A$105,0))) | H29: =IF($C29="","",Dasar2+INDEX(Kartu!$G$6:$G$105,MATCH($C29,Kartu!$A$6:$A$105,0))) | I29: =IF($C29="","",Dasar3+INDEX(Kartu!$H$6:$H$105,MATCH($C29,Kartu!$A$6:$A$105,0))) | J29: =IF($C29="","",Dasar4+INDEX(Kartu!$I$6:$I$105,MATCH($C29,Kartu!$A$6:$A$105,0))) | K29: =IF($C29="","",Dasar5+INDEX(Kartu!$J$6:$J$105,MATCH($C29,Kartu!$A$6:$A$105,0))) | L29: =IF($C29="","",L28*(1+G29)) | M29: =IF($C29="","",M28*(1+H29)) | N29: =IF($C29="","",N28*(1+I29)) | O29: =IF($C29="","",O28*(1+J29)) | P29: =IF($C29="","",P28*(1+K29)) | Q29: =IF($C29="","",Q28*(1+G29)) | R29: =IF($C29="","",R28*(1+H29)) | S29: =IF($C29="","",S28*(1+I29)) | T29: =IF($C29="","",T28*(1+J29)) | U29: =IF($C29="","",U28*(1+K29))
A30: 25 | B30: 3 | E30: =IF($C30="","",INDEX(Kartu!$C$6:$C$105,MATCH($C30,Kartu!$A$6:$A$105,0))) | F30: =IF($C30="","",INDEX(Kartu!$B$6:$B$105,MATCH($C30,Kartu!$A$6:$A$105,0))) | G30: =IF($C30="","",Dasar1+INDEX(Kartu!$F$6:$F$105,MATCH($C30,Kartu!$A$6:$A$105,0))) | H30: =IF($C30="","",Dasar2+INDEX(Kartu!$G$6:$G$105,MATCH($C30,Kartu!$A$6:$A$105,0))) | I30: =IF($C30="","",Dasar3+INDEX(Kartu!$H$6:$H$105,MATCH($C30,Kartu!$A$6:$A$105,0))) | J30: =IF($C30="","",Dasar4+INDEX(Kartu!$I$6:$I$105,MATCH($C30,Kartu!$A$6:$A$105,0))) | K30: =IF($C30="","",Dasar5+INDEX(Kartu!$J$6:$J$105,MATCH($C30,Kartu!$A$6:$A$105,0))) | L30: =IF($C30="","",L29*(1+G30)) | M30: =IF($C30="","",M29*(1+H30)) | N30: =IF($C30="","",N29*(1+I30)) | O30: =IF($C30="","",O29*(1+J30)) | P30: =IF($C30="","",P29*(1+K30)) | Q30: =IF($C30="","",Q29*(1+G30)) | R30: =IF($C30="","",R29*(1+H30)) | S30: =IF($C30="","",S29*(1+I30)) | T30: =IF($C30="","",T29*(1+J30)) | U30: =IF($C30="","",U29*(1+K30))
A31: 26 | B31: 3 | E31: =IF($C31="","",INDEX(Kartu!$C$6:$C$105,MATCH($C31,Kartu!$A$6:$A$105,0))) | F31: =IF($C31="","",INDEX(Kartu!$B$6:$B$105,MATCH($C31,Kartu!$A$6:$A$105,0))) | G31: =IF($C31="","",Dasar1+INDEX(Kartu!$F$6:$F$105,MATCH($C31,Kartu!$A$6:$A$105,0))) | H31: =IF($C31="","",Dasar2+INDEX(Kartu!$G$6:$G$105,MATCH($C31,Kartu!$A$6:$A$105,0))) | I31: =IF($C31="","",Dasar3+INDEX(Kartu!$H$6:$H$105,MATCH($C31,Kartu!$A$6:$A$105,0))) | J31: =IF($C31="","",Dasar4+INDEX(Kartu!$I$6:$I$105,MATCH($C31,Kartu!$A$6:$A$105,0))) | K31: =IF($C31="","",Dasar5+INDEX(Kartu!$J$6:$J$105,MATCH($C31,Kartu!$A$6:$A$105,0))) | L31: =IF($C31="","",L30*(1+G31)) | M31: =IF($C31="","",M30*(1+H31)) | N31: =IF($C31="","",N30*(1+I31)) | O31: =IF($C31="","",O30*(1+J31)) | P31: =IF($C31="","",P30*(1+K31)) | Q31: =IF($C31="","",Q30*(1+G31)) | R31: =IF($C31="","",R30*(1+H31)) | S31: =IF($C31="","",S30*(1+I31)) | T31: =IF($C31="","",T30*(1+J31)) | U31: =IF($C31="","",U30*(1+K31))
A32: 27 | B32: 3 | E32: =IF($C32="","",INDEX(Kartu!$C$6:$C$105,MATCH($C32,Kartu!$A$6:$A$105,0))) | F32: =IF($C32="","",INDEX(Kartu!$B$6:$B$105,MATCH($C32,Kartu!$A$6:$A$105,0))) | G32: =IF($C32="","",Dasar1+INDEX(Kartu!$F$6:$F$105,MATCH($C32,Kartu!$A$6:$A$105,0))) | H32: =IF($C32="","",Dasar2+INDEX(Kartu!$G$6:$G$105,MATCH($C32,Kartu!$A$6:$A$105,0))) | I32: =IF($C32="","",Dasar3+INDEX(Kartu!$H$6:$H$105,MATCH($C32,Kartu!$A$6:$A$105,0))) | J32: =IF($C32="","",Dasar4+INDEX(Kartu!$I$6:$I$105,MATCH($C32,Kartu!$A$6:$A$105,0))) | K32: =IF($C32="","",Dasar5+INDEX(Kartu!$J$6:$J$105,MATCH($C32,Kartu!$A$6:$A$105,0))) | L32: =IF($C32="","",L31*(1+G32)) | M32: =IF($C32="","",M31*(1+H32)) | N32: =IF($C32="","",N31*(1+I32)) | O32: =IF($C32="","",O31*(1+J32)) | P32: =IF($C32="","",P31*(1+K32)) | Q32: =IF($C32="","",Q31*(1+G32)) | R32: =IF($C32="","",R31*(1+H32)) | S32: =IF($C32="","",S31*(1+I32)) | T32: =IF($C32="","",T31*(1+J32)) | U32: =IF($C32="","",U31*(1+K32))
A33: 28 | B33: 3 | E33: =IF($C33="","",INDEX(Kartu!$C$6:$C$105,MATCH($C33,Kartu!$A$6:$A$105,0))) | F33: =IF($C33="","",INDEX(Kartu!$B$6:$B$105,MATCH($C33,Kartu!$A$6:$A$105,0))) | G33: =IF($C33="","",Dasar1+INDEX(Kartu!$F$6:$F$105,MATCH($C33,Kartu!$A$6:$A$105,0))) | H33: =IF($C33="","",Dasar2+INDEX(Kartu!$G$6:$G$105,MATCH($C33,Kartu!$A$6:$A$105,0))) | I33: =IF($C33="","",Dasar3+INDEX(Kartu!$H$6:$H$105,MATCH($C33,Kartu!$A$6:$A$105,0))) | J33: =IF($C33="","",Dasar4+INDEX(Kartu!$I$6:$I$105,MATCH($C33,Kartu!$A$6:$A$105,0))) | K33: =IF($C33="","",Dasar5+INDEX(Kartu!$J$6:$J$105,MATCH($C33,Kartu!$A$6:$A$105,0))) | L33: =IF($C33="","",L32*(1+G33)) | M33: =IF($C33="","",M32*(1+H33)) | N33: =IF($C33="","",N32*(1+I33)) | O33: =IF($C33="","",O32*(1+J33)) | P33: =IF($C33="","",P32*(1+K33)) | Q33: =IF($C33="","",Q32*(1+G33)) | R33: =IF($C33="","",R32*(1+H33)) | S33: =IF($C33="","",S32*(1+I33)) | T33: =IF($C33="","",T32*(1+J33)) | U33: =IF($C33="","",U32*(1+K33))
A34: 29 | B34: 3 | E34: =IF($C34="","",INDEX(Kartu!$C$6:$C$105,MATCH($C34,Kartu!$A$6:$A$105,0))) | F34: =IF($C34="","",INDEX(Kartu!$B$6:$B$105,MATCH($C34,Kartu!$A$6:$A$105,0))) | G34: =IF($C34="","",Dasar1+INDEX(Kartu!$F$6:$F$105,MATCH($C34,Kartu!$A$6:$A$105,0))) | H34: =IF($C34="","",Dasar2+INDEX(Kartu!$G$6:$G$105,MATCH($C34,Kartu!$A$6:$A$105,0))) | I34: =IF($C34="","",Dasar3+INDEX(Kartu!$H$6:$H$105,MATCH($C34,Kartu!$A$6:$A$105,0))) | J34: =IF($C34="","",Dasar4+INDEX(Kartu!$I$6:$I$105,MATCH($C34,Kartu!$A$6:$A$105,0))) | K34: =IF($C34="","",Dasar5+INDEX(Kartu!$J$6:$J$105,MATCH($C34,Kartu!$A$6:$A$105,0))) | L34: =IF($C34="","",L33*(1+G34)) | M34: =IF($C34="","",M33*(1+H34)) | N34: =IF($C34="","",N33*(1+I34)) | O34: =IF($C34="","",O33*(1+J34)) | P34: =IF($C34="","",P33*(1+K34)) | Q34: =IF($C34="","",Q33*(1+G34)) | R34: =IF($C34="","",R33*(1+H34)) | S34: =IF($C34="","",S33*(1+I34)) | T34: =IF($C34="","",T33*(1+J34)) | U34: =IF($C34="","",U33*(1+K34))
A35: 30 | B35: 3 | E35: =IF($C35="","",INDEX(Kartu!$C$6:$C$105,MATCH($C35,Kartu!$A$6:$A$105,0))) | F35: =IF($C35="","",INDEX(Kartu!$B$6:$B$105,MATCH($C35,Kartu!$A$6:$A$105,0))) | G35: =IF($C35="","",Dasar1+INDEX(Kartu!$F$6:$F$105,MATCH($C35,Kartu!$A$6:$A$105,0))) | H35: =IF($C35="","",Dasar2+INDEX(Kartu!$G$6:$G$105,MATCH($C35,Kartu!$A$6:$A$105,0))) | I35: =IF($C35="","",Dasar3+INDEX(Kartu!$H$6:$H$105,MATCH($C35,Kartu!$A$6:$A$105,0))) | J35: =IF($C35="","",Dasar4+INDEX(Kartu!$I$6:$I$105,MATCH($C35,Kartu!$A$6:$A$105,0))) | K35: =IF($C35="","",Dasar5+INDEX(Kartu!$J$6:$J$105,MATCH($C35,Kartu!$A$6:$A$105,0))) | L35: =IF($C35="","",L34*(1+G35)) | M35: =IF($C35="","",M34*(1+H35)) | N35: =IF($C35="","",N34*(1+I35)) | O35: =IF($C35="","",O34*(1+J35)) | P35: =IF($C35="","",P34*(1+K35)) | Q35: =IF($C35="","",Q34*(1+G35)) | R35: =IF($C35="","",R34*(1+H35)) | S35: =IF($C35="","",S34*(1+I35)) | T35: =IF($C35="","",T34*(1+J35)) | U35: =IF($C35="","",U34*(1+K35))

Sheet Input
A1: Waktu | B1: Kode | C1: Nama | D1: Tahap | E1: Sukuk | F1: Saham | G1: RDPU | H1: Emas | I1: Campuran | J1: Email | K1: Column1 | L1: Tabel 'tblInput' diisi otomatis oleh Power Automate dari Microsoft Forms.
B2: p01 | C2: Dzul | D2: 1 | E2: 50 | F2: 20 | G2: 30 | H2: 0 | I2: 0 | L2: Porsi diisi dalam persen utuh (contoh: 20 = 20%). Tahap = 1, 2, atau 3. Submission terakhir per kode & tahap yang dipakai.
B3: p02 | C3: pandu | D3: 1 | E3: 20 | F3: 30 | G3: 50 | H3: 0 | I3: 0 | L3: Contoh baris valid: 2026-10-01 08:30 | P01 | Tim Ijarah | 1 | 20 | 30 | 10 | 20 | 20
B4: p01 | D4: 2

Sheet Peserta
B2: Daftar Kode Peserta
B3: Bagikan satu kode per peserta/tim saat registrasi. Nama diambil otomatis dari form; kolom Nama di sini hanya cadangan.
A5: Kode | B5: Nama cadangan (opsional) | C5: Keterangan
A6: P01
A7: P02
A8: P03
A9: P04
A10: P05
A11: P06
A12: P07
A13: P08
A14: P09
A15: P10
A16: P11
A17: P12
... A65: P60

Sheet Perhitungan
B2: Perhitungan Nilai Aset Peserta
B3: Semua otomatis. Status merah = input peserta perlu diperbaiki (submit ulang form).
A5: Kode | B5: Nama | C5: Baris nama | D5: T1 baris | E5: T1 Sukuk/SBN | F5: T1 Saham | G5: T1 RD Pasar Uang | H5: T1 Emas | I5: T1 RD Campuran | J5: T1 total | K5: Status T1 | L5: T2 baris | M5: T2 Sukuk/SBN | N5: T2 Saham | O5: T2 RD Pasar Uang | P5: T2 Emas | Q5: T2 RD Campuran | R5: T2 total | S5: Status T2 | T5: T3 baris | U5: T3 Sukuk/SBN | V5: T3 Saham | W5: T3 RD Pasar Uang | X5: T3 Emas | Y5: T3 RD Campuran | Z5: T3 total | AA5: Status T3 | AB5: Efektif T1 Sukuk/SBN | AC5: Efektif T1 Saham | AD5: Efektif T1 RD Pasar Uang | AE5: Efektif T1 Emas | AF5: Efektif T1 RD Campuran | AG5: Efektif T2 Sukuk/SBN | AH5: Efektif T2 Saham | AI5: Efektif T2 RD Pasar Uang | AJ5: Efektif T2 Emas | AK5: Efektif T2 RD Campuran | AL5: Efektif T3 Sukuk/SBN | AM5: Efektif T3 Saham | AN5: Efektif T3 RD Pasar Uang | AO5: Efektif T3 Emas | AP5: Efektif T3 RD Campuran | AQ5: Aktif | AR5: Awal | AS5: K1 | AT5: K2 | AU5: K3 | AV5: K4 | AW5: K5 | AX5: K6 | AY5: K7 | AZ5: K8 | BA5: K9 | BB5: K10 | BC5: K11 | BD5: K12 | BE5: K13 | BF5: K14 | BG5: K15 | BH5: K16 | BI5: K17 | BJ5: K18 | BK5: K19 | BL5: K20 | BM5: K21 | BN5: K22 | BO5: K23 | BP5: K24 | BQ5: K25 | BR5: K26 | BS5: K27 | BT5: K28 | BU5: K29 | BV5: K30 | BW5: Nilai kini | BX5: Nilai lalu | BY5: Return | BZ5: Max drawdown | CA5: Skor kini | CB5: Peringkat | CC5: Skor lalu | CD5: Peringkat lalu | CE5: Naik/turun | CF5: Skor tangguh
